# 目录不存在问题【已解决】

```python
D:\Anaconda\envs\yolo11_D\python.exe D:\Document\GitHub\White-box\Diffusion\ddpm\train.py 
Epoch 1/200, Train Loss: 0.2104: 100%|██████████| 390/390 [01:54<00:00,  3.41it/s]
Epoch 1/200, Test Loss: 0.0213: 100%|██████████| 78/78 [00:07<00:00,  9.83it/s]
Sampling: 1000it [00:14, 69.78it/s]
Traceback (most recent call last):
  File "D:\Document\GitHub\White-box\Diffusion\ddpm\train.py", line 103, in <module>
    model = train(model, train_loader, test_loader, noise_scheduler, criterion, optimizer, device, args.epochs, args.img_size)
  File "D:\Document\GitHub\White-box\Diffusion\ddpm\train.py", line 84, in train
    fig.savefig(f"samples/epoch_{epoch}.png")
  File "D:\Anaconda\envs\yolo11_D\lib\site-packages\matplotlib\figure.py", line 3378, in savefig
    self.canvas.print_figure(fname, **kwargs)
  File "D:\Anaconda\envs\yolo11_D\lib\site-packages\matplotlib\backend_bases.py", line 2366, in print_figure
    result = print_method(
  File "D:\Anaconda\envs\yolo11_D\lib\site-packages\matplotlib\backend_bases.py", line 2232, in <lambda>
    print_method = functools.wraps(meth)(lambda *args, **kwargs: meth(
  File "D:\Anaconda\envs\yolo11_D\lib\site-packages\matplotlib\backends\backend_agg.py", line 509, in print_png
    self._print_pil(filename_or_obj, "png", pil_kwargs, metadata)
  File "D:\Anaconda\envs\yolo11_D\lib\site-packages\matplotlib\backends\backend_agg.py", line 458, in _print_pil
    mpl.image.imsave(
  File "D:\Anaconda\envs\yolo11_D\lib\site-packages\matplotlib\image.py", line 1689, in imsave
    image.save(fname, **pil_kwargs)
  File "D:\Anaconda\envs\yolo11_D\lib\site-packages\PIL\Image.py", line 2563, in save
    fp = builtins.open(filename, "w+b")
FileNotFoundError: [Errno 2] No such file or directory: 'D:\\Document\\GitHub\\White-box\\Diffusion\\ddpm\\samples\\epoch_0.png'

Process finished with exit code 1

```

From the error message:

```
FileNotFoundError: [Errno 2] No such file or directory: 'D:\\Document\\GitHub\\White-box\\Diffusion\\ddpm\\samples\\epoch_0.png'
```

the immediate cause is that the code tries to save the figure in the directory `samples/` under `ddpm/`, but that directory does not exist. You can fix this by making sure that directory is created before saving the file.

In other words, before calling:

```python
fig.savefig(f"samples/epoch_{epoch}.png")
```

you should ensure the `samples` directory is present. One quick way is to add something like:

```python
import os

os.makedirs("samples", exist_ok=True)
```

right before saving the figure. This tells Python to create the `samples` directory if it doesn’t already exist. That should eliminate the `FileNotFoundError`.